<?xml version="1.0" encoding="utf-8"?>
<!-- =================================================================================== -->
<!-- |    This document was autogenerated by xacro from armstrong.urdf.xacro           | -->
<!-- |    EDITING THIS FILE BY HAND IS NOT RECOMMENDED                                 | -->
<!-- =================================================================================== -->
<robot name="armstrong">
  <!-- ================ CONSTANTS ================ -->
  <!-- ================ MACROS ================ -->
  <!-- ================ GAZEBO SETTINGS  ================ -->
  <!-- Support for multiple controllers -->
  <gazebo>
    <plugin filename="libgazebo_ros_control.so" name="gazebo_ros_control">
      <robotNamespace>/</robotNamespace>
    </plugin>
  </gazebo>
  <gazebo reference="base_link">
    <turnGravityOff>false</turnGravityOff>
  </gazebo>
  <gazebo reference="frame">
    <turnGravityOff>false</turnGravityOff>
    <selfCollide>0</selfCollide>
  </gazebo>
  <gazebo reference="l_wheel">
    <selfCollide>false</selfCollide>
    <mu1 value="0.5"/>
    <mu2 value="0.5"/>
    <kp value="10000000"/>
    <kd value="1"/>
    <fdir1 value="1 0 0"/>
    <turnGravityOff>false</turnGravityOff>
    <selfCollide>0</selfCollide>
  </gazebo>
  <gazebo reference="r_wheel">
    <selfCollide>false</selfCollide>
    <mu1 value="0.5"/>
    <mu2 value="0.5"/>
    <kp value="10000000"/>
    <kd value="1"/>
    <fdir1 value="1 0 0"/>
    <turnGravityOff>false</turnGravityOff>
    <selfCollide>0</selfCollide>
  </gazebo>
  <gazebo reference="f_caster_arm">
    <turnGravityOff>false</turnGravityOff>
    <selfCollide>0</selfCollide>
    <implicitSpringDamper>True</implicitSpringDamper>
  </gazebo>
  <gazebo reference="r_caster_wheel">
    <turnGravityOff>false</turnGravityOff>
    <selfCollide>0</selfCollide>
    <implicitSpringDamper>True</implicitSpringDamper>
     --&gt;
  
  </gazebo>
  <gazebo reference="b_caster_wheel">
    <turnGravityOff>false</turnGravityOff>
    <selfCollide>0</selfCollide>
    <implicitSpringDamper>True</implicitSpringDamper>
     --&gt;
  
  </gazebo>
  <gazebo reference="b_caster_arm">
    <turnGravityOff>false</turnGravityOff>
    <selfCollide>0</selfCollide>
    <implicitSpringDamper>True</implicitSpringDamper>
     --&gt;
  
  </gazebo>
  <gazebo reference="link_1">
    <turnGravityOff>false</turnGravityOff>
    <selfCollide>False</selfCollide>
    <implicitSpringDamper>True</implicitSpringDamper>
  </gazebo>
  <gazebo reference="link_2">
    <turnGravityOff>false</turnGravityOff>
    <selfCollide>False</selfCollide>
    <implicitSpringDamper>True</implicitSpringDamper>
  </gazebo>
  <gazebo reference="link_3">
    <turnGravityOff>false</turnGravityOff>
    <selfCollide>False</selfCollide>
    <implicitSpringDamper>True</implicitSpringDamper>
  </gazebo>
  <gazebo reference="link_4">
    <turnGravityOff>false</turnGravityOff>
    <selfCollide>False</selfCollide>
    <implicitSpringDamper>True</implicitSpringDamper>
  </gazebo>
  <gazebo reference="link_5">
    <turnGravityOff>false</turnGravityOff>
    <selfCollide>False</selfCollide>
    <implicitSpringDamper>True</implicitSpringDamper>
  </gazebo>
  <gazebo reference="link_6">
    <turnGravityOff>false</turnGravityOff>
    <selfCollide>False</selfCollide>
    <implicitSpringDamper>True</implicitSpringDamper>
  </gazebo>
  <gazebo reference="r_finger">
    <turnGravityOff>false</turnGravityOff>
    <selfCollide>False</selfCollide>
    <implicitSpringDamper>True</implicitSpringDamper>
  </gazebo>
  <!-- ================ BASE LINK - DUMMY ================ -->
  <link name="base_link"/>
  <!-- ================ FRAME LINK ================ -->
  <link name="frame">
    <visual>
      <geometry>
        <mesh filename="package://armstrong_description/meshes/frame.dae"/>
      </geometry>
    </visual>
    <collision>
      <origin rpy="0 0 0" xyz="0 0 0"/>
      <geometry>
        <mesh filename="package://armstrong_description/meshes/frame.dae"/>
      </geometry>
    </collision>
    <inertial>
      <origin rpy="0 0 0" xyz="0 0 0"/>
      <mass value="9.748"/>
      <inertia ixx="0.0001" ixy="0.000" ixz="0.000" iyy="0.0001" iyz="0.000" izz="0.0001"/>
    </inertial>
  </link>
  <!-- ================ LEFT WHEEL LINK ================ -->
  <link name="l_wheel">
    <visual>
      <geometry>
        <mesh filename="package://armstrong_description/meshes/l_wheel.dae"/>
      </geometry>
    </visual>
    <collision>
      <origin rpy="0 1.570796 0" xyz="0 0 0"/>
      <geometry>
        <cylinder length="0.027844" radius="0.076875"/>
      </geometry>
    </collision>
    <inertial>
      <origin rpy="0 1.570796 0" xyz="0 0 0"/>
      <mass value="0.635"/>
      <inertia ixx="0.0001" ixy="0.000" ixz="0.000" iyy="0.0001" iyz="0.000" izz="0.0001"/>
    </inertial>
  </link>
  <!-- ================ RIGHT WHEEL LINK ================ -->
  <link name="r_wheel">
    <visual>
      <geometry>
        <mesh filename="package://armstrong_description/meshes/r_wheel.dae"/>
      </geometry>
    </visual>
    <collision>
      <origin rpy="0 1.570796 0" xyz="0 0 0"/>
      <geometry>
        <cylinder length="0.027844" radius="0.076875"/>
      </geometry>
    </collision>
    <inertial>
      <origin rpy="0 1.570796 0" xyz="0 0 0"/>
      <mass value="0.635"/>
      <inertia ixx="0.0001" ixy="0.000" ixz="0.000" iyy="0.0001" iyz="0.000" izz="0.0001"/>
    </inertial>
  </link>
  <!-- ================ FRONT CASTER ARM LINK ================ -->
  <link name="f_caster_arm">
    <visual>
      <geometry>
        <mesh filename="package://armstrong_description/meshes/caster_arm.dae"/>
      </geometry>
    </visual>
    <collision>
      <origin rpy="0 0 0" xyz="0 0 0"/>
      <geometry>
        <mesh filename="package://armstrong_description/meshes/caster_arm.dae"/>
      </geometry>
    </collision>
    <inertial>
      <origin rpy="0 0 0" xyz="0 0 0"/>
      <mass value="0.048"/>
      <inertia ixx="0.0001" ixy="0.000" ixz="0.000" iyy="0.0001" iyz="0.000" izz="0.0001"/>
    </inertial>
  </link>
  <!-- ================ FRONT CASTER WHEELS LINK ================ -->
  <link name="f_caster_wheels">
    <visual>
      <geometry>
        <mesh filename="package://armstrong_description/meshes/caster_wheels.dae"/>
      </geometry>
    </visual>
    <collision>
      <origin rpy="0 0 0" xyz="0 0 0"/>
      <geometry>
        <mesh filename="package://armstrong_description/meshes/caster_wheels.dae"/>
      </geometry>
    </collision>
    <inertial>
      <origin rpy="0 0 0" xyz="0 0 0"/>
      <mass value="0.1516"/>
      <inertia ixx="0.0001" ixy="0.000" ixz="0.000" iyy="0.0001" iyz="0.000" izz="0.0001"/>
    </inertial>
  </link>
  <!-- ================ BACK CASTER ARM LINK ================ -->
  <link name="b_caster_arm">
    <visual>
      <geometry>
        <mesh filename="package://armstrong_description/meshes/caster_arm.dae"/>
      </geometry>
    </visual>
    <collision>
      <origin rpy="0 0 0" xyz="0 0 0"/>
      <geometry>
        <mesh filename="package://armstrong_description/meshes/caster_arm.dae"/>
      </geometry>
    </collision>
    <inertial>
      <origin rpy="0 0 0" xyz="0 0 0"/>
      <mass value="0.048"/>
      <inertia ixx="0.0001" ixy="0.000" ixz="0.000" iyy="0.0001" iyz="0.000" izz="0.0001"/>
    </inertial>
  </link>
  <!-- ================ BACK CASTER WHEELS LINK ================ -->
  <link name="b_caster_wheels">
    <visual>
      <geometry>
        <mesh filename="package://armstrong_description/meshes/caster_wheels.dae"/>
      </geometry>
    </visual>
    <collision>
      <origin rpy="0 0 0" xyz="0 0 0"/>
      <geometry>
        <mesh filename="package://armstrong_description/meshes/caster_wheels.dae"/>
      </geometry>
    </collision>
    <inertial>
      <origin rpy="0 0 0" xyz="0 0 0"/>
      <mass value="0.1516"/>
      <inertia ixx="0.0001" ixy="0.000" ixz="0.000" iyy="0.0001" iyz="0.000" izz="0.0001"/>
    </inertial>
  </link>
  <!-- ================ LINK1 LINK ================ -->
  <link name="link_1">
    <visual>
      <geometry>
        <mesh filename="package://armstrong_description/meshes/link_1.dae"/>
      </geometry>
    </visual>
    <collision>
      <origin rpy="0 0 0" xyz="0 0 0"/>
      <geometry>
        <mesh filename="package://armstrong_description/meshes/link_1.dae"/>
      </geometry>
    </collision>
    <inertial>
      <origin rpy="0 0 0" xyz="0 0 0"/>
      <mass value="0.266262084814045"/>
      <inertia ixx="0.0001" ixy="0.000" ixz="0.000" iyy="0.0001" iyz="0.000" izz="0.0001"/>
    </inertial>
  </link>
  <!-- ================ LINK2 LINK ================ -->
  <link name="link_2">
    <visual>
      <geometry>
        <mesh filename="package://armstrong_description/meshes/link_2.dae"/>
      </geometry>
    </visual>
    <collision>
      <origin rpy="0 0 0" xyz="0 0 0"/>
      <geometry>
        <mesh filename="package://armstrong_description/meshes/link_2.dae"/>
      </geometry>
    </collision>
    <inertial>
      <origin rpy="0 0 0" xyz="0 0 0"/>
      <mass value="0.20557"/>
      <inertia ixx="0.0001" ixy="0.000" ixz="0.000" iyy="0.0001" iyz="0.000" izz="0.0001"/>
    </inertial>
  </link>
  <!-- ================ LINK3 LINK ================ -->
  <link name="link_3">
    <visual>
      <geometry>
        <mesh filename="package://armstrong_description/meshes/link_3.dae"/>
      </geometry>
    </visual>
    <collision>
      <origin rpy="0 0 0" xyz="0 0 0"/>
      <geometry>
        <mesh filename="package://armstrong_description/meshes/link_3.dae"/>
      </geometry>
    </collision>
    <inertial>
      <origin rpy="0 0 0" xyz="0 0 0"/>
      <mass value="0.145524"/>
      <inertia ixx="0.0001" ixy="0.000" ixz="0.000" iyy="0.0001" iyz="0.000" izz="0.0001"/>
    </inertial>
  </link>
  <!-- ================ LINK4 LINK ================ -->
  <link name="link_4">
    <visual>
      <geometry>
        <mesh filename="package://armstrong_description/meshes/link_4.dae"/>
      </geometry>
    </visual>
    <collision>
      <origin rpy="0 0 0" xyz="0 0 0"/>
      <geometry>
        <mesh filename="package://armstrong_description/meshes/link_4.dae"/>
      </geometry>
    </collision>
    <inertial>
      <origin rpy="0 0 0" xyz="0 0 0"/>
      <mass value="0.1"/>
      <inertia ixx="0.0001" ixy="0.000" ixz="0.000" iyy="0.0001" iyz="0.000" izz="0.0001"/>
    </inertial>
  </link>
  <!-- ================ LINK5 LINK ================ -->
  <link name="link_5">
    <visual>
      <geometry>
        <mesh filename="package://armstrong_description/meshes/link_5.dae"/>
      </geometry>
    </visual>
    <collision>
      <origin rpy="0 0 0" xyz="0 0 0"/>
      <geometry>
        <mesh filename="package://armstrong_description/meshes/link_5.dae"/>
      </geometry>
    </collision>
    <inertial>
      <origin rpy="0 0 0" xyz="0 0 0"/>
      <mass value="0.092731"/>
      <inertia ixx="0.0001" ixy="0.000" ixz="0.000" iyy="0.0001" iyz="0.000" izz="0.0001"/>
    </inertial>
  </link>
  <!-- ================ LINK6 LINK ================ -->
  <link name="link_6">
    <visual>
      <geometry>
        <mesh filename="package://armstrong_description/meshes/link_6.dae"/>
      </geometry>
    </visual>
    <collision>
      <origin rpy="0 0 0" xyz="0 0 0"/>
      <geometry>
        <mesh filename="package://armstrong_description/meshes/link_6.dae"/>
      </geometry>
    </collision>
    <inertial>
      <origin rpy="0 0 0" xyz="0 0 0"/>
      <mass value="0.12368"/>
      <inertia ixx="0.0001" ixy="0.000" ixz="0.000" iyy="0.0001" iyz="0.000" izz="0.0001"/>
    </inertial>
  </link>
  <!-- ================ R_FINGER LINK ================ -->
  <link name="r_finger">
    <visual>
      <geometry>
        <mesh filename="package://armstrong_description/meshes/r_finger.dae"/>
      </geometry>
    </visual>
    <collision>
      <origin rpy="0 0 0" xyz="0 0 0"/>
      <geometry>
        <mesh filename="package://armstrong_description/meshes/r_finger.dae"/>
      </geometry>
    </collision>
    <inertial>
      <origin rpy="0 0 0" xyz="0 0 0"/>
      <mass value="0.027053"/>
      <inertia ixx="0.0001" ixy="0.000" ixz="0.000" iyy="0.0001" iyz="0.000" izz="0.0001"/>
    </inertial>
  </link>
  <!-- ================ L_FINGER LINK ================ -->
  <link name="l_finger">
    <visual>
      <geometry>
        <mesh filename="package://armstrong_description/meshes/l_finger.dae"/>
      </geometry>
    </visual>
    <collision>
      <origin rpy="0 0 0" xyz="0 0 0"/>
      <geometry>
        <mesh filename="package://armstrong_description/meshes/l_finger.dae"/>
      </geometry>
    </collision>
    <inertial>
      <origin rpy="0 0 0" xyz="0 0 0"/>
      <mass value="0.027053"/>
      <inertia ixx="0.0001" ixy="0.000" ixz="0.000" iyy="0.0001" iyz="0.000" izz="0.0001"/>
    </inertial>
  </link>
  <!-- ================ END EFFECTOR SPHERE LINK ================ -->
  <link name="end_effector">
    <visual>
      <geometry>
        <sphere radius="0.0001"/>
      </geometry>
    </visual>
    <inertial>
      <origin rpy="0 0 0" xyz="0 0 0"/>
      <mass value="0"/>
      <inertia ixx="0.0001" ixy="0.000" ixz="0.000" iyy="0.0001" iyz="0.000" izz="0.0001"/>
    </inertial>
  </link>
  <!-- ================ FRAME JOINT ================ -->
  <joint name="joint_base_link" type="fixed">
    <parent link="base_link"/>
    <child link="frame"/>
    <origin rpy="0 0 0" xyz="0 0 0"/>
  </joint>
  <!-- ================ LEFT WHEEL JOINT ================ -->
  <joint name="joint_l_wheel" type="continuous">
    <parent link="frame"/>
    <child link="l_wheel"/>
    <origin rpy="0 0 -3.141593"  xyz="-0.18729 0 0"/>
    <axis xyz="1 0 0"/>
  </joint>
  <transmission name="l_wheel_trans">
    <type>transmission_interface/SimpleTransmission</type>
    <joint name="joint_l_wheel">
      <hardwareInterface>hardware_interface/VelocityJointInterface</hardwareInterface>
    </joint>
    <actuator name="right_wheel_actuator">
      <mechanicalReduction> 1 </mechanicalReduction>
      <hardwareInterface>VelocityJointInterface</hardwareInterface>
    </actuator>
  </transmission>
  <!-- ================ RIGHT WHEEL JOINT ================ -->
  <joint name="joint_r_wheel" type="continuous">
    <parent link="frame"/>
    <child link="r_wheel"/>
    <origin rpy="0 0 -3.141593"  xyz="0.18729 0 0"/>
    <axis xyz="1 0 0"/>
  </joint>
  <transmission name="r_wheel_trans">
    <type>transmission_interface/SimpleTransmission</type>
    <joint name="joint_r_wheel">
      <hardwareInterface>hardware_interface/VelocityJointInterface</hardwareInterface>
    </joint>
    <actuator name="right_wheel_actuator">
      <mechanicalReduction> 1 </mechanicalReduction>
      <hardwareInterface>VelocityJointInterface</hardwareInterface>
    </actuator>
  </transmission>
  <!-- ================ FRONT CASTER ARM JOINT ================ -->
  <joint name="joint_f_caster_arm" type="continuous">
    <parent link="frame"/>
    <child link="f_caster_arm"/>
    <origin xyz="0 -0.18518 0.0168" />
    <axis xyz="0 0 1"/>
  </joint>
  <!-- ================ FRONT CASTER WHEELS JOINT ================ -->
  <joint name="joint_f_caster_wheels" type="continuous">
    <parent link="f_caster_arm"/>
    <child link="f_caster_wheels"/>
    <origin xyz="0 0.0387 -0.0525" />
    <axis xyz="1 0 0"/>
  </joint>
  <!-- ================ BACK CASTER ARM JOINT ================ -->
  <joint name="joint_b_caster_arm" type="continuous">
    <parent link="frame"/>
    <child link="b_caster_arm"/>
    <origin xyz="0 0.18518 0.0168" />
    <axis xyz="0 0 1"/>
  </joint>
  <!-- ================ BACK CASTER WHEELS JOINT ================ -->
  <joint name="joint_b_caster_wheels" type="continuous">
    <parent link="b_caster_arm"/>
    <child link="b_caster_wheels"/>
    <origin xyz="0 0.0387 -0.0525" />
    <axis xyz="1 0 0"/>
  </joint>
  <!-- ================ LINK1 JOINT ================ -->
  <joint name="joint_1" type="revolute">
    <parent link="frame"/>
    <child link="link_1"/>
    <origin rpy="0 0 0" xyz="0 0.15508 0.076053"/>
    <axis xyz="0 0 1"/>
    <limit effort="24" lower="-1.5708" upper="1.5708" velocity="6.07"/>
  </joint>
  <transmission name="joint_1_transmission">
    <type>transmission_interface/SimpleTransmission</type>
    <joint name="joint_1">
      <hardwareInterface>hardware_interface/PositionJointInterface</hardwareInterface>
    </joint>
    <actuator name="joint_1_actuator">
      <hardwareInterface>hardware_interface/PositionJointInterface</hardwareInterface>
      <mechanicalReduction>1</mechanicalReduction>
    </actuator>
  </transmission>
  <!-- ================ LINK2 JOINT ================ -->
  <joint name="joint_2" type="revolute">
    <parent link="link_1"/>
    <child link="link_2"/>
    <origin rpy="0 0 0" xyz="0 0 0.058757"/>
    <axis xyz="1 0 0"/>
    <limit effort="48" lower="-1.91288086" upper="1.91288086" velocity="6.07"/>
  </joint>
  <transmission name="joint_2_transmission">
    <type>transmission_interface/SimpleTransmission</type>
    <joint name="joint_2">
      <hardwareInterface>hardware_interface/PositionJointInterface</hardwareInterface>
    </joint>
    <actuator name="joint_2_actuator">
      <hardwareInterface>hardware_interface/PositionJointInterface</hardwareInterface>
      <mechanicalReduction>1</mechanicalReduction>
    </actuator>
  </transmission>
  <!-- ================ LINK3 JOINT ================ -->
  <joint name="joint_3" type="revolute">
    <parent link="link_2"/>
    <child link="link_3"/>
    <origin rpy="0 0 0" xyz="0 0.031055 0.189"/>
    <axis xyz="1 0 0"/>
    <limit effort="24" lower="-2.7227136" upper="2.7227136" velocity="6.07"/>
  </joint>
  <transmission name="joint_3_transmission">
    <type>transmission_interface/SimpleTransmission</type>
    <joint name="joint_3">
      <hardwareInterface>hardware_interface/PositionJointInterface</hardwareInterface>
    </joint>
    <actuator name="joint_3_actuator">
      <hardwareInterface>hardware_interface/PositionJointInterface</hardwareInterface>
      <mechanicalReduction>1</mechanicalReduction>
    </actuator>
  </transmission>
  <!-- ================ LINK4 JOINT ================ -->
  <joint name="joint_4" type="revolute">
    <parent link="link_3"/>
    <child link="link_4"/>
    <origin rpy="0 0 0" xyz="0 0 0.0855"/>
    <axis xyz="0 0 1"/>
    <limit effort="24" lower="-3.14159265" upper="3.14159265" velocity="6.07"/>
  </joint>
  <transmission name="joint_4_transmission">
    <type>transmission_interface/SimpleTransmission</type>
    <joint name="joint_4">
      <hardwareInterface>hardware_interface/PositionJointInterface</hardwareInterface>
    </joint>
    <actuator name="joint_4_actuator">
      <hardwareInterface>hardware_interface/PositionJointInterface</hardwareInterface>
      <mechanicalReduction>1</mechanicalReduction>
    </actuator>
  </transmission>
  <!-- ================ LINK5 JOINT ================ -->
  <joint name="joint_5" type="revolute">
    <parent link="link_4"/>
    <child link="link_5"/>
    <origin rpy="0 0 0" xyz="0 0 0.066188"/>
    <axis xyz="1 0 0"/>
    <limit effort="24" lower="-1.91288086" upper="1.91288086" velocity="6.07"/>
  </joint>
  <transmission name="joint_5_transmission">
    <type>transmission_interface/SimpleTransmission</type>
    <joint name="joint_5">
      <hardwareInterface>hardware_interface/PositionJointInterface</hardwareInterface>
    </joint>
    <actuator name="joint_5_actuator">
      <hardwareInterface>hardware_interface/PositionJointInterface</hardwareInterface>
      <mechanicalReduction>1</mechanicalReduction>
    </actuator>
  </transmission>
  <!-- ================ LINK6 JOINT ================ -->
  <joint name="joint_6" type="revolute">
    <parent link="link_5"/>
    <child link="link_6"/>
    <origin rpy="0 0 0" xyz="0 -0.016024 0.08458"/>
    <axis xyz="0 0 1"/>
    <limit effort="10" lower="-2.617993878" upper="2.617993878" velocity="6.07"/>
  </joint>
  <transmission name="joint_6_transmission">
    <type>transmission_interface/SimpleTransmission</type>
    <joint name="joint_6">
      <hardwareInterface>hardware_interface/PositionJointInterface</hardwareInterface>
    </joint>
    <actuator name="joint_6_actuator">
      <hardwareInterface>hardware_interface/PositionJointInterface</hardwareInterface>
      <mechanicalReduction>1</mechanicalReduction>
    </actuator>
  </transmission>
  <!-- ================ R_FINGER JOINT ================ -->
  <joint name="joint_r_finger" type="revolute">
    <parent link="link_6"/>
    <child link="r_finger"/>
    <origin rpy="0 0 0" xyz="0.01853 -0.000527 0.05403"/>
    <axis xyz="0 1 0"/>
    <limit effort="10" lower="-0.40" upper="0" velocity="6.07"/>
  </joint>
  <transmission name="joint_r_finger_transmission">
    <type>transmission_interface/SimpleTransmission</type>
    <joint name="joint_r_finger">
      <hardwareInterface>hardware_interface/PositionJointInterface</hardwareInterface>
    </joint>
    <actuator name="joint_r_finger_actuator">
      <hardwareInterface>hardware_interface/PositionJointInterface</hardwareInterface>
      <mechanicalReduction>1</mechanicalReduction>
    </actuator>
  </transmission>
  <!-- ================ L_FINGER JOINT ================ -->
  <joint name="joint_l_finger" type="revolute">
    <parent link="link_6"/>
    <child link="l_finger"/>
    <origin rpy="0 0 0" xyz="-0.01853 -0.000527 0.05403"/>
    <axis xyz="0 1 0"/>
    <limit effort="10" lower="0" upper="0.40" velocity="6.07"/>
  </joint>
  <transmission name="joint_l_finger_transmission">
    <type>transmission_interface/SimpleTransmission</type>
    <joint name="joint_l_finger">
      <hardwareInterface>hardware_interface/PositionJointInterface</hardwareInterface>
    </joint>
    <actuator name="joint_l_finger_actuator">
      <hardwareInterface>hardware_interface/PositionJointInterface</hardwareInterface>
      <mechanicalReduction>1</mechanicalReduction>
    </actuator>
  </transmission>
  <!-- ================ END EFFECTOR JOINT ================ -->
  <joint name="joint_end_effector" type="fixed">
    <parent link="link_6"/>
    <child link="end_effector"/>
    <origin rpy="0 0 0" xyz="0 -0.077462 0.083028"/>
  </joint>
</robot>
