<?xml version="1.0" encoding="utf-8"?>
<!-- =================================================================================== -->
<!-- |    This document was autogenerated by xacro from axel.urdf.xacro                | -->
<!-- |    EDITING THIS FILE BY HAND IS NOT RECOMMENDED                                 | -->
<!-- =================================================================================== -->
<robot name="axel">
  <!-- ================ CONSTANTS ================ -->
  <!-- ================ MACROS ================ -->
  <!-- ================ GAZEBO SETTINGS  ================ -->
  <!-- Support for multiple controllers -->
  <gazebo>
    <plugin filename="libgazebo_ros_control.so" name="gazebo_ros_control">
      <robotNamespace>/</robotNamespace>
    </plugin>
  </gazebo>
  <gazebo reference="base_link">
    <turnGravityOff>false</turnGravityOff>
  </gazebo>
  <gazebo reference="frame">
    <turnGravityOff>false</turnGravityOff>
    <selfCollide>0</selfCollide>
  </gazebo>
  <gazebo reference="booms">
    <turnGravityOff>false</turnGravityOff>
    <selfCollide>0</selfCollide>
  </gazebo>
  <gazebo reference="l_wheel">
    <mu1 value="200.0"/>
    <mu2 value="100.0"/>
    <kp value="10000000.0"/>
    <kd value="1.0"/>
  </gazebo>
  <gazebo reference="r_wheel">
    <mu1 value="200.0"/>
    <mu2 value="100.0"/>
    <kp value="10000000.0"/>
    <kd value="1.0"/>
  </gazebo>
  <!-- ================ BASE LINK - DUMMY ================ -->
  <link name="base_link"/>
  <!-- ================ FRAME LINK ================ -->
  <link name="frame">
    <visual>
      <origin rpy="0 0 0" xyz="0 0 0"/>
      <geometry>
        <mesh filename="package://axel_description/meshes/frame.dae"/>
      </geometry>
    </visual>
    <collision>
      <origin rpy="0 0 0" xyz="0 0 0"/>
      <geometry>
        <mesh filename="package://axel_description/meshes/frame.dae"/>
      </geometry>
    </collision>
    <inertial>
      <origin rpy="1.57079632679 0 0" xyz="0 0 0"/>
      <mass value="20"/>
      <inertia ixx="5.78042791667" ixy="0" ixz="0" iyy="5.78042791667" iyz="0" izz="1.2355225"/>
    </inertial>
  </link>
  <!-- ================ BOOMS LINK ================ -->
  <link name="booms">
    <visual>
      <origin rpy="0 0 0" xyz="0 0 0"/>
      <geometry>
        <mesh filename="package://axel_description/meshes/booms.dae"/>
      </geometry>
    </visual>
    <collision>
      <origin rpy="0 0 0" xyz="0 0 0"/>
      <geometry>
        <mesh filename="package://axel_description/meshes/booms.dae"/>
      </geometry>
    </collision>
    <inertial>
      <origin rpy="1.57079632679 0 0" xyz="-0.88275 0 0"/>
      <mass value="40"/>
      <inertia ixx="1.570" ixy="-0.567" ixz="0.343" iyy="1.44" iyz="0.606" izz="1.407"/>
    </inertial>
  </link>
  <!-- ================ LEFT WHEEL LINK ================ -->
  <link name="l_wheel">
    <visual>
      <origin rpy="0 0 1.57079632679" xyz="0 0 0"/>
      <geometry>
        <mesh filename="package://axel_description/meshes/wheel.dae"/>
      </geometry>
    </visual>
    <collision>
      <origin rpy="1.57079632679 0 1.57079632679" xyz="0 0 0"/>
      <geometry>
        <cylinder length="0.410568" radius="0.74547"/>
      </geometry>
    </collision>
    <inertial>
      <origin rpy="1.57079632679 0 1.57079632679" xyz="0 0 0"/>
      <mass value="10"/>
      <inertia ixx="1.52978553777" ixy="0" ixz="0" iyy="1.52978553777" iyz="0" izz="2.7786276045"/>
    </inertial>
  </link>
  <!-- ================ RIGHT WHEEL LINK ================ -->
  <link name="r_wheel">
    <visual>
      <origin rpy="3.14159265358 0 1.57079632679" xyz="0 0 0"/>
      <geometry>
        <mesh filename="package://axel_description/meshes/wheel.dae"/>
      </geometry>
    </visual>
    <collision>
      <origin rpy="1.57079632679 0 1.57079632679" xyz="0 0 0"/>
      <geometry>
        <cylinder length="0.410568" radius="0.74547"/>
      </geometry>
    </collision>
    <inertial>
      <origin rpy="1.57079632679 0 1.57079632679" xyz="0 0 0"/>
      <mass value="10"/>
      <inertia ixx="1.52978553777" ixy="0" ixz="0" iyy="1.52978553777" iyz="0" izz="2.7786276045"/>
    </inertial>
  </link>
  <!-- ================ FRAME JOINT ================ -->
  <joint name="joint_base_link" type="fixed">
    <parent link="base_link"/>
    <child link="frame"/>
    <origin rpy="0 0 0" xyz="0 0 0"/>
  </joint>
  <!-- ================ BOOMS JOINT ================ -->
  <joint name="joint_booms" type="fixed">
    <parent link="frame"/>
    <child link="booms"/>
    <origin rpy="0 0 0" xyz="0 0 0"/>
  </joint>
  <!-- ================ RIGHT WHEEL JOINT ================ -->
  <joint name="joint_r_wheel" type="continuous">
    <parent link="frame"/>
    <child link="r_wheel"/>
    <origin rpy="0 0 1.57079632679" xyz="0 -0.97524 0"/>
    <axis xyz="1 0 0"/>
  </joint>
  <transmission name="r_wheel_trans">
    <type>transmission_interface/SimpleTransmission</type>
    <joint name="joint_r_wheel">
      <hardwareInterface>hardware_interface/VelocityJointInterface</hardwareInterface>
    </joint>
    <actuator name="right_wheel_actuator">
      <mechanicalReduction> 1 </mechanicalReduction>
      <hardwareInterface>VelocityJointInterface</hardwareInterface>
    </actuator>
  </transmission>
  <!-- ================ LEFT WHEEL JOINT ================ -->
  <joint name="joint_l_wheel" type="continuous">
    <parent link="frame"/>
    <child link="l_wheel"/>
    <origin rpy="0 0 1.57079632679" xyz="0 0.97524 0"/>
    <axis xyz="1 0 0"/>
    <limit effort="30" velocity="1.0"/>
  </joint>
  <transmission name="l_wheel_trans">
    <type>transmission_interface/SimpleTransmission</type>
    <joint name="joint_l_wheel">
      <hardwareInterface>hardware_interface/VelocityJointInterface</hardwareInterface>
    </joint>
    <actuator name="left_wheel_actuator">
      <mechanicalReduction> 1 </mechanicalReduction>
      <hardwareInterface>VelocityJointInterface</hardwareInterface>
    </actuator>
  </transmission>
</robot>
