<?xml version="1.0" encoding="utf-8"?>
<!-- =================================================================================== -->
<!-- |    This document was autogenerated by xacro from legstrong.urdf.xacro           | -->
<!-- |    EDITING THIS FILE BY HAND IS NOT RECOMMENDED                                 | -->
<!-- =================================================================================== -->
<robot name="legstrong">
  <!-- ================ CONSTANTS ================ -->
  <!-- ================ MACROS ================ -->
  <!-- ================ BASE LINK - DUMMY ================ -->
  <link name="base_link"/>
  <!-- ================ FRAME LINK ================ -->
  <link name="frame">
    <visual>
      <geometry>
        <mesh filename="package://legstrong_description/meshes/frame.dae"/>
      </geometry>
    </visual>
    <collision>
      <origin rpy="0 0 0" xyz="0 0 0"/>
      <geometry>
        <mesh filename="package://legstrong_description/meshes/frame.dae"/>
      </geometry>
    </collision>
    <inertial>
      <origin rpy="0 0 0" xyz="0.012  0.002 0.067"/>
      <mass value="9.748"/>
      <inertia ixx="0.15604" ixy="-0.01985" ixz="-0.00008" iyy="0.14019" iyz="-0.00045" izz="0.12027"/>
    </inertial>
  </link>
  <!-- ================ LEFT WHEEL LINK ================ -->
  <link name="l_wheel">
    <visual>
      <!-- <origin rpy="0 1.5708 0" xyz="0 0 0"/> -->
      <!-- Set to p=1.5708 when using the cylinder collidor -->
      <geometry>
        <mesh filename="package://legstrong_description/meshes/l_wheel.dae"/>
        <!-- <cylinder radius="${wheel_radius}" length="${wheel_width}"/> -->
      </geometry>
    </visual>
    <collision>
      <origin rpy="0 1.5708 0" xyz="0 0 0"/>
      <geometry>
        <cylinder length="0.027844" radius="0.076875"/>
      </geometry>
    </collision>
    <inertial>
      <origin rpy="0 0 0" xyz="0 0 0"/>
      <mass value="0.635"/>
      <inertia ixx="0.0009" ixy="0.0" ixz="0.0" iyy="0.00089" iyz="0.0" izz="0.00172"/>
    </inertial>
  </link>
  <!-- ================ RIGHT WHEEL LINK ================ -->
  <link name="r_wheel">
    <visual>
      <!-- <origin rpy="0 1.5708 0" xyz="0 0 0"/> -->
      <geometry>
        <mesh filename="package://legstrong_description/meshes/r_wheel.dae"/>
        <!-- <cylinder radius="${wheel_radius}" length="${wheel_width}"/> -->
      </geometry>
    </visual>
    <collision>
      <origin rpy="0 1.5708 0" xyz="0 0 0"/>
      <geometry>
        <cylinder length="0.027844" radius="0.076875"/>
      </geometry>
    </collision>
    <inertial>
      <origin rpy="0 0 0" xyz="0 0 0"/>
      <mass value="0.635"/>
      <inertia ixx="0.0009" ixy="0.0" ixz="0.0" iyy="0.00089" iyz="0.0" izz="0.00172"/>
    </inertial>
  </link>
  <!-- ================ FRONT CASTER ARM LINK ================ -->
  <link name="f_caster_arm">
    <visual>
      <geometry>
        <mesh filename="package://legstrong_description/meshes/caster_arm.dae"/>
      </geometry>
    </visual>
    <collision>
      <origin rpy="0 0 0" xyz="0 0 0"/>
      <geometry>
        <mesh filename="package://legstrong_description/meshes/caster_arm.dae"/>
      </geometry>
    </collision>
    <inertial>
      <origin rpy="0 0 0" xyz="0 0 0"/>
      <mass value="0.1"/>
      <inertia ixx="0.00005" ixy="0.00001" ixz="0.0" iyy="0.00001" iyz="0.0" izz="0.00003"/>
    </inertial>
  </link>
  <!-- ================ FRONT CASTER WHEELS LINK ================ -->
  <link name="f_caster_wheels">
    <visual>
      <geometry>
        <mesh filename="package://legstrong_description/meshes/caster_wheels.dae"/>
      </geometry>
    </visual>
    <collision>
      <origin rpy="0 0 0" xyz="0 0 0"/>
      <geometry>
        <mesh filename="package://legstrong_description/meshes/caster_wheels.dae"/>
      </geometry>
    </collision>
    <inertial>
      <origin rpy="0 0 0" xyz="0 0 0"/>
      <mass value="0.1516"/>
      <inertia ixx="0.0001" ixy="0.0" ixz="0.0" iyy="0.0001" iyz="0.0" izz="0.0001"/>
    </inertial>
  </link>
  <!-- ================ BACK CASTER ARM LINK ================ -->
  <link name="b_caster_arm">
    <visual>
      <geometry>
        <mesh filename="package://legstrong_description/meshes/caster_arm.dae"/>
      </geometry>
    </visual>
    <collision>
      <origin rpy="0 0 0" xyz="0 0 0"/>
      <geometry>
        <mesh filename="package://legstrong_description/meshes/caster_arm.dae"/>
      </geometry>
    </collision>
    <inertial>
      <origin rpy="0 0 0" xyz="0 0 0"/>
      <mass value="0.1"/>
      <inertia ixx="0.00005" ixy="0.00001" ixz="0.0" iyy="0.00001" iyz="0.0" izz="0.00003"/>
    </inertial>
  </link>
  <!-- ================ BACK CASTER WHEELS LINK ================ -->
  <link name="b_caster_wheels">
    <visual>
      <geometry>
        <mesh filename="package://legstrong_description/meshes/caster_wheels.dae"/>
      </geometry>
    </visual>
    <collision>
      <origin rpy="0 0 0" xyz="0 0 0"/>
      <geometry>
        <mesh filename="package://legstrong_description/meshes/caster_wheels.dae"/>
      </geometry>
    </collision>
    <inertial>
      <origin rpy="0 0 0" xyz="0 0 0"/>
      <mass value="0.1516"/>
      <inertia ixx="0.0001" ixy="0.0" ixz="0.0" iyy="0.0001" iyz="0.0" izz="0.0001"/>
    </inertial>
  </link>
  <!-- ================ FRAME JOINT ================ -->
  <joint name="joint_base_link" type="fixed">
    <parent link="base_link"/>
    <child link="frame"/>
    <origin rpy="0 0 0" xyz="0 0 0"/>
  </joint>
  <!-- ================ LEFT WHEEL JOINT ================ -->
  <joint name="joint_l_wheel" type="continuous">
    <parent link="frame"/>
    <child link="l_wheel"/>
    <origin rpy="0 0 0" xyz="0.18729 0 0"/>
    <axis xyz="1 0 0"/>
  </joint>
  <transmission name="l_wheel_trans">
    <type>transmission_interface/SimpleTransmission</type>
    <joint name="joint_l_wheel">
      <hardwareInterface>hardware_interface/VelocityJointInterface</hardwareInterface>
    </joint>
    <actuator name="left_wheel_actuator">
      <mechanicalReduction> 1 </mechanicalReduction>
      <hardwareInterface>VelocityJointInterface</hardwareInterface>
    </actuator>
  </transmission>
  <!-- ================ RIGHT WHEEL JOINT ================ -->
  <joint name="joint_r_wheel" type="continuous">
    <parent link="frame"/>
    <child link="r_wheel"/>
    <origin rpy="0 0 0" xyz="-0.18729 0 0"/>
    <axis xyz="1 0 0"/>
  </joint>
  <transmission name="r_wheel_trans">
    <type>transmission_interface/SimpleTransmission</type>
    <joint name="joint_r_wheel">
      <hardwareInterface>hardware_interface/VelocityJointInterface</hardwareInterface>
    </joint>
    <actuator name="right_wheel_actuator">
      <mechanicalReduction> 1 </mechanicalReduction>
      <hardwareInterface>VelocityJointInterface</hardwareInterface>
    </actuator>
  </transmission>
  <!-- ================ FRONT CASTER ARM JOINT ================ -->
  <joint name="joint_f_caster_arm" type="continuous">
    <parent link="frame"/>
    <child link="f_caster_arm"/>
    <origin rpy="0 0 0" xyz="0 -0.18518 0.006469"/>
    <axis xyz="0 0 1"/>
  </joint>
  <!-- ================ FRONT CASTER WHEELS JOINT ================ -->
  <joint name="joint_f_caster_wheels" type="continuous">
    <parent link="f_caster_arm"/>
    <child link="f_caster_wheels"/>
    <origin rpy="0 0 0" xyz="0 0.0387 -0.0419"/>
    <axis xyz="1 0 0"/>
  </joint>
  <!-- ================ BACK CASTER ARM JOINT ================ -->
  <joint name="joint_b_caster_arm" type="continuous">
    <parent link="frame"/>
    <child link="b_caster_arm"/>
    <origin rpy="0 0 0" xyz="0 0.18518 0.006469"/>
    <axis xyz="0 0 1"/>
  </joint>
  <!-- ================ BACK CASTER WHEELS JOINT ================ -->
  <joint name="joint_b_caster_wheels" type="continuous">
    <parent link="b_caster_arm"/>
    <child link="b_caster_wheels"/>
    <origin rpy="0 0 0" xyz="0 0.0387 -0.0419"/>
    <axis xyz="1 0 0"/>
  </joint>

  <gazebo>
    <plugin filename="libgazebo_ros_control.so" name="gazebo_ros_control">
      <robotNamespace>/</robotNamespace>
    </plugin>
  </gazebo>
  <gazebo reference="base_link">
    <turnGravityOff>false</turnGravityOff>
  </gazebo>
  <gazebo reference="frame">
    <turnGravityOff>false</turnGravityOff>
    <selfCollide>0</selfCollide>
    <!-- <implicitSpringDamper>True</implicitSpringDamper> -->
  </gazebo>
  <gazebo reference="l_wheel">
    <selfCollide>false</selfCollide>
    <mu1 value="0.5"/>
    <mu2 value="0.5"/>
    <kp value="10000000"/>
    <kd value="1"/>
    <fdir1 value="1 0 0"/>
    <turnGravityOff>false</turnGravityOff>
    <selfCollide>0</selfCollide>
    <!-- <implicitSpringDamper>True</implicitSpringDamper> -->
  </gazebo>
  <gazebo reference="r_wheel">
    <selfCollide>false</selfCollide>
    <mu1 value="0.5"/>
    <mu2 value="0.5"/>
    <kp value="10000000"/>
    <kd value="1"/>
    <fdir1 value="1 0 0"/>
    <turnGravityOff>false</turnGravityOff>
    <selfCollide>0</selfCollide>
    <!-- <implicitSpringDamper>True</implicitSpringDamper> -->
  </gazebo>
  <gazebo reference="f_caster_arm">
    <turnGravityOff>false</turnGravityOff>
    <selfCollide>0</selfCollide>
    <implicitSpringDamper>True</implicitSpringDamper>
  </gazebo>
  <gazebo reference="r_caster_wheel">
    <turnGravityOff>false</turnGravityOff>
    <selfCollide>0</selfCollide>
    <implicitSpringDamper>True</implicitSpringDamper>
     --&gt;
  
  </gazebo>
  <gazebo reference="b_caster_wheel">
    <turnGravityOff>false</turnGravityOff>
    <selfCollide>0</selfCollide>
    <implicitSpringDamper>True</implicitSpringDamper>
     --&gt;
  
  </gazebo>
  <gazebo reference="b_caster_arm">
    <turnGravityOff>false</turnGravityOff>
    <selfCollide>0</selfCollide>
    <implicitSpringDamper>True</implicitSpringDamper>
     --&gt;
  
  </gazebo>
  <!-- <gazebo reference="link_1">
    <turnGravityOff>false</turnGravityOff>
    <selfCollide>False</selfCollide>
    <implicitSpringDamper>True</implicitSpringDamper>
  </gazebo>  

  <gazebo reference="link_2">
    <turnGravityOff>false</turnGravityOff>
    <selfCollide>False</selfCollide>
    <implicitSpringDamper>True</implicitSpringDamper>
  </gazebo>
  
  <gazebo reference="link_3">
    <turnGravityOff>false</turnGravityOff>
    <selfCollide>False</selfCollide>
    <implicitSpringDamper>True</implicitSpringDamper>
  </gazebo>  

  <gazebo reference="link_4">
    <turnGravityOff>false</turnGravityOff>
    <selfCollide>False</selfCollide>
    <implicitSpringDamper>True</implicitSpringDamper>
  </gazebo>  

  <gazebo reference="link_5">
    <turnGravityOff>false</turnGravityOff>
    <selfCollide>False</selfCollide>
    <implicitSpringDamper>True</implicitSpringDamper>
  </gazebo>  

  <gazebo reference="link_6">
    <turnGravityOff>false</turnGravityOff>
    <selfCollide>False</selfCollide>
    <implicitSpringDamper>True</implicitSpringDamper>
  </gazebo>  

  <gazebo reference="r_finger">
    <turnGravityOff>false</turnGravityOff>
    <selfCollide>False</selfCollide>
    <implicitSpringDamper>True</implicitSpringDamper>
  </gazebo>  
   -->
</robot>
