<?xml version="1.0" encoding="utf-8" ?>
<!-- =================================================================================== -->
<!-- |    This document was autogenerated by xacro from /home/mason/catkin_ws/src/legstrong_description/urdf/legstrong.urdf.xacro | -->
<!-- |    EDITING THIS FILE BY HAND IS NOT RECOMMENDED                                 | -->
<!-- =================================================================================== -->
<robot name="armstrong">
    <!-- ================ CONSTANTS ================ -->
    <!-- ================ MACROS ================ -->
    <!-- ================ GAZEBO SETTINGS  ================ -->
    <gazebo>
        <plugin filename="libgazebo_ros_control.so" name="gazebo_ros_control">
            <robotNamespace>/</robotNamespace>
        </plugin>
    </gazebo>
    <gazebo reference="world">
        <turnGravityOff>false</turnGravityOff>
    </gazebo>
    <!-- ================ WORLD ================ -->
    <link name="world" />
    <!-- ================ FRAME LINK ================ -->
    <link name="frame">
        <visual>
            <geometry>
                <mesh filename="package://legstrong_description/meshes/frame.dae" />
            </geometry>
        </visual>
        <collision>
            <origin rpy="0 0 0" xyz="0 0 0" />
            <geometry>
                <mesh filename="package://legstrong_description/meshes/frame.dae" />
            </geometry>
        </collision>
        
<inertial>
            <origin rpy="0 0 0" xyz="0 0 0" />
            <mass value="9.748" />
            <inertia ixx="0.0001" ixy="0.000" ixz="0.000" iyy="0.0001" iyz="0.000" izz="0.0001" />
        </inertial>

    </link>
    <!-- ================ LEFT WHEEL LINK ================ -->
    <link name="l_wheel">
        <visual>
            <geometry>
                <mesh filename="package://legstrong_description/meshes/l_wheel.dae" />
            </geometry>
        </visual>
        <collision>
            <origin rpy="0 0 0" xyz="0 0 0" />
            <geometry>
                <cylinder length="0.027844" radius="0.76875" />
            </geometry>
        </collision>
        
<inertial>
            <origin rpy="0 0 0" xyz="0 0 0" />
            <mass value="0.635" />
            <inertia ixx="0.0001" ixy="0.000" ixz="0.000" iyy="0.0001" iyz="0.000" izz="0.0001" />
        </inertial>

    </link>
    <!-- ================ RIGHT WHEEL LINK ================ -->
    <link name="r_wheel">
        <visual>
            <geometry>
                <mesh filename="package://legstrong_description/meshes/r_wheel.dae" />
            </geometry>
        </visual>
        <collision>
            <origin rpy="0 0 0" xyz="0 0 0" />
            <geometry>
                <cylinder length="0.027844" radius="0.76875" />
            </geometry>
        </collision>
        
<inertial>
            <origin rpy="0 0 0" xyz="0 0 0" />
            <mass value="0.635" />
            <inertia ixx="0.0001" ixy="0.000" ixz="0.000" iyy="0.0001" iyz="0.000" izz="0.0001" />
        </inertial>

    </link>
    <!-- ================ FRONT CASTER ARM LINK ================ -->
    <link name="f_caster_arm">
        <visual>
            <geometry>
                <mesh filename="package://legstrong_description/meshes/caster_arm.dae" />
            </geometry>
        </visual>
        <collision>
            <origin rpy="0 0 0" xyz="0 0 0" />
            <geometry>
                <mesh filename="package://legstrong_description/meshes/caster_arm.dae" />
            </geometry>
        </collision>
        
<inertial>
            <origin rpy="0 0 0" xyz="0 0 0" />
            <mass value="0.048" />
            <inertia ixx="0.0001" ixy="0.000" ixz="0.000" iyy="0.0001" iyz="0.000" izz="0.0001" />
        </inertial>

    </link>
    <!-- ================ FRONT CASTER WHEELS LINK ================ -->
    <link name="f_caster_wheels">
        <visual>
            <geometry>
                <mesh filename="package://legstrong_description/meshes/caster_wheels.dae" />
            </geometry>
        </visual>
        <collision>
            <origin rpy="0 0 0" xyz="0 0 0" />
            <geometry>
                <mesh filename="package://legstrong_description/meshes/caster_wheels.dae" />
            </geometry>
        </collision>
        
<inertial>
            <origin rpy="0 0 0" xyz="0 0 0" />
            <mass value="0.1516" />
            <inertia ixx="0.0001" ixy="0.000" ixz="0.000" iyy="0.0001" iyz="0.000" izz="0.0001" />
        </inertial>

    </link>
    <!-- ================ BACK CASTER ARM LINK ================ -->
    <link name="b_caster_arm">
        <visual>
            <geometry>
                <mesh filename="package://legstrong_description/meshes/caster_arm.dae" />
            </geometry>
        </visual>
        <collision>
            <origin rpy="0 0 0" xyz="0 0 0" />
            <geometry>
                <mesh filename="package://legstrong_description/meshes/caster_arm.dae" />
            </geometry>
        </collision>
        
<inertial>
            <origin rpy="0 0 0" xyz="0 0 0" />
            <mass value="0.048" />
            <inertia ixx="0.0001" ixy="0.000" ixz="0.000" iyy="0.0001" iyz="0.000" izz="0.0001" />
        </inertial>

    </link>
    <!-- ================ BACK CASTER WHEELS LINK ================ -->
    <link name="b_caster_wheels">
        <visual>
            <geometry>
                <mesh filename="package://legstrong_description/meshes/caster_wheels.dae" />
            </geometry>
        </visual>
        <collision>
            <origin rpy="0 0 0" xyz="0 0 0" />
            <geometry>
                <mesh filename="package://legstrong_description/meshes/caster_wheels.dae" />
            </geometry>
        </collision>
        
<inertial>
            <origin rpy="0 0 0" xyz="0 0 0" />
            <mass value="0.1516" />
            <inertia ixx="0.0001" ixy="0.000" ixz="0.000" iyy="0.0001" iyz="0.000" izz="0.0001" />
        </inertial>

    </link>
    <!-- ================ LINK1 LINK ================ -->
    <link name="link_1">
        <visual>
            <geometry>
                <mesh filename="package://legstrong_description/meshes/link_1.dae" />
            </geometry>
        </visual>
        <collision>
            <origin rpy="0 0 0" xyz="0 0 0" />
            <geometry>
                <mesh filename="package://legstrong_description/meshes/link_1.dae" />
            </geometry>
        </collision>
        
<inertial>
            <origin rpy="0 0 0" xyz="0 0 0" />
            <mass value="0.266262084814045" />
            <inertia ixx="0.0001" ixy="0.000" ixz="0.000" iyy="0.0001" iyz="0.000" izz="0.0001" />
        </inertial>

    </link>
    <!-- ================ LINK2 LINK ================ -->
    <link name="link_2">
        <visual>
            <geometry>
                <mesh filename="package://legstrong_description/meshes/link_2.dae" />
            </geometry>
        </visual>
        <collision>
            <origin rpy="0 0 0" xyz="0 0 0" />
            <geometry>
                <mesh filename="package://legstrong_description/meshes/link_2.dae" />
            </geometry>
        </collision>
        
<inertial>
            <origin rpy="0 0 0" xyz="0 0 0" />
            <mass value="0.20557" />
            <inertia ixx="0.0001" ixy="0.000" ixz="0.000" iyy="0.0001" iyz="0.000" izz="0.0001" />
        </inertial>

    </link>
    <!-- ================ LINK3 LINK ================ -->
    <link name="link_3">
        <visual>
            <geometry>
                <mesh filename="package://legstrong_description/meshes/link_3.dae" />
            </geometry>
        </visual>
        <collision>
            <origin rpy="0 0 0" xyz="0 0 0" />
            <geometry>
                <mesh filename="package://legstrong_description/meshes/link_3.dae" />
            </geometry>
        </collision>
        
<inertial>
            <origin rpy="0 0 0" xyz="0 0 0" />
            <mass value="0.145524" />
            <inertia ixx="0.0001" ixy="0.000" ixz="0.000" iyy="0.0001" iyz="0.000" izz="0.0001" />
        </inertial>

    </link>
    <!-- ================ LINK4 LINK ================ -->
    <link name="link_4">
        <visual>
            <geometry>
                <mesh filename="package://legstrong_description/meshes/link_4.dae" />
            </geometry>
        </visual>
        <collision>
            <origin rpy="0 0 0" xyz="0 0 0" />
            <geometry>
                <mesh filename="package://legstrong_description/meshes/link_4.dae" />
            </geometry>
        </collision>
        
<inertial>
            <origin rpy="0 0 0" xyz="0 0 0" />
            <mass value="1" />
            <inertia ixx="0.0001" ixy="0.000" ixz="0.000" iyy="0.0001" iyz="0.000" izz="0.0001" />
        </inertial>

    </link>
    <!-- ================ LINK5 LINK ================ -->
    <link name="link_5">
        <visual>
            <geometry>
                <mesh filename="package://legstrong_description/meshes/link_5.dae" />
            </geometry>
        </visual>
        <collision>
            <origin rpy="0 0 0" xyz="0 0 0" />
            <geometry>
                <mesh filename="package://legstrong_description/meshes/link_5.dae" />
            </geometry>
        </collision>
        
<inertial>
            <origin rpy="0 0 0" xyz="0 0 0" />
            <mass value="0.092731" />
            <inertia ixx="0.0001" ixy="0.000" ixz="0.000" iyy="0.0001" iyz="0.000" izz="0.0001" />
        </inertial>

    </link>
    <!-- ================ LINK6 LINK ================ -->
    <link name="link_6">
        <visual>
            <geometry>
                <mesh filename="package://legstrong_description/meshes/link_6.dae" />
            </geometry>
        </visual>
        <collision>
            <origin rpy="0 0 0" xyz="0 0 0" />
            <geometry>
                <mesh filename="package://legstrong_description/meshes/link_6.dae" />
            </geometry>
        </collision>
        
<inertial>
            <origin rpy="0 0 0" xyz="0 0 0" />
            <mass value="0.12368" />
            <inertia ixx="0.0001" ixy="0.000" ixz="0.000" iyy="0.0001" iyz="0.000" izz="0.0001" />
        </inertial>

    </link>
    <!-- ================ R_FINGER LINK ================ -->
    <link name="r_finger">
        <visual>
            <geometry>
                <mesh filename="package://legstrong_description/meshes/r_finger.dae" />
            </geometry>
        </visual>
        <collision>
            <origin rpy="0 0 0" xyz="0 0 0" />
            <geometry>
                <mesh filename="package://legstrong_description/meshes/r_finger.dae" />
            </geometry>
        </collision>
        
<inertial>
            <origin rpy="0 0 0" xyz="0 0 0" />
            <mass value="0.027053" />
            <inertia ixx="0.0001" ixy="0.000" ixz="0.000" iyy="0.0001" iyz="0.000" izz="0.0001" />
        </inertial>

    </link>
    <!-- ================ L_FINGER LINK ================ -->
    <link name="l_finger">
        <visual>
            <geometry>
                <mesh filename="package://legstrong_description/meshes/l_finger.dae" />
            </geometry>
        </visual>
        <collision>
            <origin rpy="0 0 0" xyz="0 0 0" />
            <geometry>
                <mesh filename="package://legstrong_description/meshes/l_finger.dae" />
            </geometry>
        </collision>
        
<inertial>
            <origin rpy="0 0 0" xyz="0 0 0" />
            <mass value="0.027053" />
            <inertia ixx="0.0001" ixy="0.000" ixz="0.000" iyy="0.0001" iyz="0.000" izz="0.0001" />
        </inertial>

    </link>
    <!-- ================ END EFFECTOR SPHERE LINK ================ -->
    <link name="end_effector">
        <visual>
            <geometry>
                <sphere radius="0.003" />
            </geometry>
        </visual>
        
<inertial>
            <origin rpy="0 0 0" xyz="0 0 0" />
            <mass value="0" />
            <inertia ixx="0.0001" ixy="0.000" ixz="0.000" iyy="0.0001" iyz="0.000" izz="0.0001" />
        </inertial>

    </link>
    <!-- ================ FRAME JOINT ================ -->
    <joint name="joint_world" type="fixed">
        <parent link="world" />
        <child link="frame" />
        <origin rpy="0 0 0" xyz="0 0 0" />
    </joint>
    <!-- ================ LEFT WHEEL JOINT ================ -->
    <joint name="joint_l_wheel" type="continuous">
        <parent link="frame" />
        <child link="l_wheel" />
        <origin rpy="0 0 0" xyz="0.18729 0 0" />
        <axis xyz="1 0 0" />
    </joint>
    
<transmission name="l_wheel_trans">
        <type>transmission_interface/SimpleTransmission</type>
        <joint name="joint_l_wheel">
            <hardwareInterface>hardware_interface/VelocityJointInterface</hardwareInterface>
        </joint>
        <actuator name="right_wheel_actuator">
            <mechanicalReduction>1</mechanicalReduction>
            <hardwareInterface>VelocityJointInterface</hardwareInterface>
        </actuator>
    </transmission>
    <!-- ================ RIGHT WHEEL JOINT ================ -->
    <joint name="joint_r_wheel" type="continuous">
        <parent link="frame" />
        <child link="r_wheel" />
        <origin rpy="0 0 0" xyz="-0.18729 0 0" />
        <axis xyz="1 0 0" />
    </joint>
    <transmission name="r_wheel_trans">
        <type>transmission_interface/SimpleTransmission</type>
        <joint name="joint_r_wheel">
            <hardwareInterface>hardware_interface/VelocityJointInterface</hardwareInterface>
        </joint>
        <actuator name="right_wheel_actuator">
            <mechanicalReduction>1</mechanicalReduction>
            <hardwareInterface>VelocityJointInterface</hardwareInterface>
        </actuator>
    </transmission>
    <!-- ================ FRONT CASTER ARM JOINT ================ -->
    <joint name="joint_f_caster_arm" type="continuous">
        <parent link="frame" />
        <child link="f_caster_arm" />
        <origin rpy="0 0 0" xyz="0 -0.18518 0.006469" />
        <axis xyz="0 0 1" />
    </joint>
    <!-- ================ FRONT CASTER WHEELS JOINT ================ -->
    <joint name="joint_f_caster_wheels" type="continuous">
        <parent link="f_caster_arm" />
        <child link="f_caster_wheels" />
        <origin rpy="0 0 0" xyz="0 0.0387 -0.0419" />
        <axis xyz="1 0 0" />
    </joint>
    <!-- ================ BACK CASTER ARM JOINT ================ -->
    <joint name="joint_b_caster_arm" type="continuous">
        <parent link="frame" />
        <child link="b_caster_arm" />
        <origin rpy="0 0 0" xyz="0 0.18518 0.006469" />
        <axis xyz="0 0 1" />
    </joint>
    <!-- ================ BACK CASTER WHEELS JOINT ================ -->
    <joint name="joint_b_caster_wheels" type="continuous">
        <parent link="b_caster_arm" />
        <child link="b_caster_wheels" />
        <origin rpy="0 0 0" xyz="0 0.0387 -0.0419" />
        <axis xyz="1 0 0" />
    </joint>
    <!-- ================ LINK1 JOINT ================ -->
    <joint name="joint_1" type="revolute">
        <parent link="frame" />
        <child link="link_1" />
        <origin rpy="0 0 0" xyz="0 -0.15508 0.076053" />
        <axis xyz="0 0 1" />
        <limit effort="24" lower="-1.5708" upper="1.5708" velocity="6.07" />
    </joint>
    <transmission name="joint_1_transmission">
        <type>transmission_interface/SimpleTransmission</type>
        <joint name="joint_1">
            <hardwareInterface>hardware_interface/PositionJointInterface</hardwareInterface>
        </joint>
        <actuator name="joint_1_actuator">
            <hardwareInterface>hardware_interface/PositionJointInterface</hardwareInterface>
            <mechanicalReduction>1</mechanicalReduction>
        </actuator>
    </transmission>
    <!-- ================ LINK2 JOINT ================ -->
    <joint name="joint_2" type="revolute">
        <parent link="link_1" />
        <child link="link_2" />
        <origin rpy="0 0 0" xyz="0 0 0.068757" />
        <axis xyz="1 0 0" />
        <limit effort="48" lower="-1.91288086" upper="1.91288086" velocity="6.07" />
    </joint>
    <transmission name="joint_2_transmission">
        <type>transmission_interface/SimpleTransmission</type>
        <joint name="joint_2">
            <hardwareInterface>hardware_interface/PositionJointInterface</hardwareInterface>
        </joint>
        <actuator name="joint_2_actuator">
            <hardwareInterface>hardware_interface/PositionJointInterface</hardwareInterface>
            <mechanicalReduction>1</mechanicalReduction>
        </actuator>
    </transmission>
    <!-- ================ LINK3 JOINT ================ -->
    <joint name="joint_3" type="revolute">
        <parent link="link_2" />
        <child link="link_3" />
        <origin rpy="0 0 0" xyz="0 -0.031055 0.18221" />
        <axis xyz="1 0 0" />
        <limit effort="24" lower="0" upper="3.14159265" velocity="6.07" />
    </joint>
    <transmission name="joint_3_transmission">
        <type>transmission_interface/SimpleTransmission</type>
        <joint name="joint_3">
            <hardwareInterface>hardware_interface/PositionJointInterface</hardwareInterface>
        </joint>
        <actuator name="joint_3_actuator">
            <hardwareInterface>hardware_interface/PositionJointInterface</hardwareInterface>
            <mechanicalReduction>1</mechanicalReduction>
        </actuator>
    </transmission>
    <!-- ================ LINK4 JOINT ================ -->
    <joint name="joint_4" type="revolute">
        <parent link="link_3" />
        <child link="link_4" />
        <origin rpy="0 0 3.14159265" xyz="0 0 0.0855" />
        <axis xyz="0 0 1" />
        <limit effort="24" lower="-3.14159265" upper="3.14159265" velocity="6.07" />
    </joint>
    <transmission name="joint_4_transmission">
        <type>transmission_interface/SimpleTransmission</type>
        <joint name="joint_4">
            <hardwareInterface>hardware_interface/PositionJointInterface</hardwareInterface>
        </joint>
        <actuator name="joint_4_actuator">
            <hardwareInterface>hardware_interface/PositionJointInterface</hardwareInterface>
            <mechanicalReduction>1</mechanicalReduction>
        </actuator>
    </transmission>
    <!-- ================ LINK5 JOINT ================ -->
    <joint name="joint_5" type="revolute">
        <parent link="link_4" />
        <child link="link_5" />
        <origin rpy="0 0 0" xyz="0 0 0.066188" />
        <axis xyz="1 0 0" />
        <limit effort="24" lower="-1.91288086" upper="1.91288086" velocity="6.07" />
    </joint>
    <transmission name="joint_5_transmission">
        <type>transmission_interface/SimpleTransmission</type>
        <joint name="joint_5">
            <hardwareInterface>hardware_interface/PositionJointInterface</hardwareInterface>
        </joint>
        <actuator name="joint_5_actuator">
            <hardwareInterface>hardware_interface/PositionJointInterface</hardwareInterface>
            <mechanicalReduction>1</mechanicalReduction>
        </actuator>
    </transmission>
    <!-- ================ LINK6 JOINT ================ -->
    <joint name="joint_6" type="revolute">
        <parent link="link_5" />
        <child link="link_6" />
        <origin rpy="0 0 0" xyz="0 -0.016024 0.08458" />
        <axis xyz="0 0 1" />
        <limit effort="10" lower="-2.617993878" upper="2.617993878" velocity="6.07" />
    </joint>
    <transmission name="joint_6_transmission">
        <type>transmission_interface/SimpleTransmission</type>
        <joint name="joint_6">
            <hardwareInterface>hardware_interface/PositionJointInterface</hardwareInterface>
        </joint>
        <actuator name="joint_6_actuator">
            <hardwareInterface>hardware_interface/PositionJointInterface</hardwareInterface>
            <mechanicalReduction>1</mechanicalReduction>
        </actuator>
    </transmission>
    <!-- ================ R_FINGER JOINT ================ -->
    <joint name="joint_r_finger" type="revolute">
        <parent link="link_6" />
        <child link="r_finger" />
        <origin rpy="0 0 0" xyz="0.01853 -0.000527 0.05403" />
        <axis xyz="0 1 0" />
        <limit effort="10" lower="-0.40" upper="0" velocity="6.07" />
    </joint>
    <transmission name="joint_r_finger_transmission">
        <type>transmission_interface/SimpleTransmission</type>
        <joint name="joint_r_finger">
            <hardwareInterface>hardware_interface/PositionJointInterface</hardwareInterface>
        </joint>
        <actuator name="joint_r_finger_actuator">
            <hardwareInterface>hardware_interface/PositionJointInterface</hardwareInterface>
            <mechanicalReduction>1</mechanicalReduction>
        </actuator>
    </transmission>
    <!-- ================ L_FINGER JOINT ================ -->
    <joint name="joint_l_finger" type="revolute">
        <parent link="link_6" />
        <child link="l_finger" />
        <origin rpy="0 0 0" xyz="-0.01853 -0.000527 0.05403" />
        <axis xyz="0 1 0" />
        <limit effort="10" lower="0" upper="0.40" velocity="6.07" />
    </joint>
    <!-- ================ END EFFECTOR JOINT ================ -->
    <joint name="joint_end_effector" type="fixed">
        <parent link="link_6" />
        <child link="end_effector" />
        <origin rpy="0 0 0" xyz="0 -0.077462 0.083028" />
    </joint>
    <transmission name="joint_l_finger_transmission">
        <type>transmission_interface/SimpleTransmission</type>
        <joint name="joint_l_finger">
            <hardwareInterface>hardware_interface/PositionJointInterface</hardwareInterface>
        </joint>
        <actuator name="joint_l_finger_actuator">
            <hardwareInterface>hardware_interface/PositionJointInterface</hardwareInterface>
            <mechanicalReduction>1</mechanicalReduction>
        </actuator>
    </transmission>
    <transmission name="trans_joint_l_wheel">
        <type>transmission_interface/SimpleTransmission</type>
        <joint name="joint_l_wheel">
            <hardwareInterface>hardware_interface/EffortJointInterface</hardwareInterface>
        </joint>
        <actuator name="joint_l_wheel_motor">
            <hardwareInterface>hardware_interface/EffortJointInterface</hardwareInterface>
            <mechanicalReduction>1</mechanicalReduction>
        </actuator>
    </transmission>
    <transmission name="trans_joint_r_wheel">
        <type>transmission_interface/SimpleTransmission</type>
        <joint name="joint_r_wheel">
            <hardwareInterface>hardware_interface/EffortJointInterface</hardwareInterface>
        </joint>
        <actuator name="joint_r_wheel_motor">
            <hardwareInterface>hardware_interface/EffortJointInterface</hardwareInterface>
            <mechanicalReduction>1</mechanicalReduction>
        </actuator>
    </transmission>
    <transmission name="trans_joint_f_caster_arm">
        <type>transmission_interface/SimpleTransmission</type>
        <joint name="joint_f_caster_arm">
            <hardwareInterface>hardware_interface/EffortJointInterface</hardwareInterface>
        </joint>
        <actuator name="joint_f_caster_arm_motor">
            <hardwareInterface>hardware_interface/EffortJointInterface</hardwareInterface>
            <mechanicalReduction>1</mechanicalReduction>
        </actuator>
    </transmission>
    <transmission name="trans_joint_f_caster_wheels">
        <type>transmission_interface/SimpleTransmission</type>
        <joint name="joint_f_caster_wheels">
            <hardwareInterface>hardware_interface/EffortJointInterface</hardwareInterface>
        </joint>
        <actuator name="joint_f_caster_wheels_motor">
            <hardwareInterface>hardware_interface/EffortJointInterface</hardwareInterface>
            <mechanicalReduction>1</mechanicalReduction>
        </actuator>
    </transmission>
    <transmission name="trans_joint_b_caster_arm">
        <type>transmission_interface/SimpleTransmission</type>
        <joint name="joint_b_caster_arm">
            <hardwareInterface>hardware_interface/EffortJointInterface</hardwareInterface>
        </joint>
        <actuator name="joint_b_caster_arm_motor">
            <hardwareInterface>hardware_interface/EffortJointInterface</hardwareInterface>
            <mechanicalReduction>1</mechanicalReduction>
        </actuator>
    </transmission>
    <transmission name="trans_joint_b_caster_wheels">
        <type>transmission_interface/SimpleTransmission</type>
        <joint name="joint_b_caster_wheels">
            <hardwareInterface>hardware_interface/EffortJointInterface</hardwareInterface>
        </joint>
        <actuator name="joint_b_caster_wheels_motor">
            <hardwareInterface>hardware_interface/EffortJointInterface</hardwareInterface>
            <mechanicalReduction>1</mechanicalReduction>
        </actuator>
    </transmission>
    <transmission name="trans_joint_1">
        <type>transmission_interface/SimpleTransmission</type>
        <joint name="joint_1">
            <hardwareInterface>hardware_interface/EffortJointInterface</hardwareInterface>
        </joint>
        <actuator name="joint_1_motor">
            <hardwareInterface>hardware_interface/EffortJointInterface</hardwareInterface>
            <mechanicalReduction>1</mechanicalReduction>
        </actuator>
    </transmission>
    <transmission name="trans_joint_2">
        <type>transmission_interface/SimpleTransmission</type>
        <joint name="joint_2">
            <hardwareInterface>hardware_interface/EffortJointInterface</hardwareInterface>
        </joint>
        <actuator name="joint_2_motor">
            <hardwareInterface>hardware_interface/EffortJointInterface</hardwareInterface>
            <mechanicalReduction>1</mechanicalReduction>
        </actuator>
    </transmission>
    <transmission name="trans_joint_3">
        <type>transmission_interface/SimpleTransmission</type>
        <joint name="joint_3">
            <hardwareInterface>hardware_interface/EffortJointInterface</hardwareInterface>
        </joint>
        <actuator name="joint_3_motor">
            <hardwareInterface>hardware_interface/EffortJointInterface</hardwareInterface>
            <mechanicalReduction>1</mechanicalReduction>
        </actuator>
    </transmission>
    <transmission name="trans_joint_4">
        <type>transmission_interface/SimpleTransmission</type>
        <joint name="joint_4">
            <hardwareInterface>hardware_interface/EffortJointInterface</hardwareInterface>
        </joint>
        <actuator name="joint_4_motor">
            <hardwareInterface>hardware_interface/EffortJointInterface</hardwareInterface>
            <mechanicalReduction>1</mechanicalReduction>
        </actuator>
    </transmission>
    <transmission name="trans_joint_5">
        <type>transmission_interface/SimpleTransmission</type>
        <joint name="joint_5">
            <hardwareInterface>hardware_interface/EffortJointInterface</hardwareInterface>
        </joint>
        <actuator name="joint_5_motor">
            <hardwareInterface>hardware_interface/EffortJointInterface</hardwareInterface>
            <mechanicalReduction>1</mechanicalReduction>
        </actuator>
    </transmission>
    <transmission name="trans_joint_6">
        <type>transmission_interface/SimpleTransmission</type>
        <joint name="joint_6">
            <hardwareInterface>hardware_interface/EffortJointInterface</hardwareInterface>
        </joint>
        <actuator name="joint_6_motor">
            <hardwareInterface>hardware_interface/EffortJointInterface</hardwareInterface>
            <mechanicalReduction>1</mechanicalReduction>
        </actuator>
    </transmission>
    <transmission name="trans_joint_r_finger">
        <type>transmission_interface/SimpleTransmission</type>
        <joint name="joint_r_finger">
            <hardwareInterface>hardware_interface/EffortJointInterface</hardwareInterface>
        </joint>
        <actuator name="joint_r_finger_motor">
            <hardwareInterface>hardware_interface/EffortJointInterface</hardwareInterface>
            <mechanicalReduction>1</mechanicalReduction>
        </actuator>
    </transmission>
    <transmission name="trans_joint_l_finger">
        <type>transmission_interface/SimpleTransmission</type>
        <joint name="joint_l_finger">
            <hardwareInterface>hardware_interface/EffortJointInterface</hardwareInterface>
        </joint>
        <actuator name="joint_l_finger_motor">
            <hardwareInterface>hardware_interface/EffortJointInterface</hardwareInterface>
            <mechanicalReduction>1</mechanicalReduction>
        </actuator>
    </transmission>
    <gazebo>
        <plugin name="gazebo_ros_control" filename="libgazebo_ros_control.so">
            <robotNamespace>/</robotNamespace>
        </plugin>
    </gazebo>
</robot>