<?xml version="1.0" encoding="utf-8"?>
<robot name="armstrong" xmlns:xacro="http://www.ros.org/wiki/xacro">

    <!-- ================ CONSTANTS ================ -->

    <xacro:property name="wheel_radius" value="0.76875"/>
    <xacro:property name="wheel_width" value="0.027844"/>
    <xacro:property name="PI" value="3.14159265358"/>

    <!-- ================ MACROS ================ -->

    <xacro:macro name="transmission_block" params="joint_name">
		<transmission name="${joint_name}_transmission">
			<type>transmission_interface/SimpleTransmission</type>
			<joint name="${joint_name}">
				<hardwareInterface>hardware_interface/PositionJointInterface</hardwareInterface>
			</joint>
			<actuator name="${joint_name}_actuator">
				<hardwareInterface>hardware_interface/PositionJointInterface</hardwareInterface>
				<mechanicalReduction>1</mechanicalReduction>
			</actuator>
		</transmission>
	</xacro:macro>
        
    <!-- ================ GAZEBO SETTINGS  ================ -->

    <xacro:include filename="$(find armstrong_description)/urdf/armstrong.gazebo" />

    <!-- ================ BASE LINK - DUMMY ================ -->
   
    <link name="base_link"/>

    <!-- ================ FRAME LINK ================ -->

    <link name="frame">
        <visual>
            <geometry>
                <mesh filename="package://armstrong_description/meshes/frame.dae"/>       
            </geometry>
        </visual>
        <collision>
            <origin rpy="0 0 0" xyz="0 0 0"/>
            <geometry>
                <mesh filename="package://armstrong_description/meshes/frame.dae"/>
            </geometry>            
        </collision>
        <inertial>
            <origin xyz="0 0 0" rpy="0 0 0" />
            <mass value="9.748" />
            <inertia ixx="0.0001" ixy="0.000"  ixz="0.000"  
            iyy="0.0001" iyz="0.000"
            izz="0.0001"
   />
        </inertial>
    </link>

    <!-- ================ LEFT WHEEL LINK ================ -->

    <link name="l_wheel">
        <visual>
            <geometry>
                <mesh filename="package://armstrong_description/meshes/l_wheel.dae"/>       
            </geometry>
        </visual>
        <collision>
            <origin rpy="0 0 0" xyz="0 0 0"/>
            <geometry>
                <cylinder radius="${wheel_radius}" length="${wheel_width}"/>
              </geometry>       
        </collision>
        <inertial>
            <origin xyz="0 0 0" rpy="0 0 0" />
            <mass value="0.635" />
            <inertia ixx="0.0001" ixy="0.000"  ixz="0.000"  
            iyy="0.0001" iyz="0.000"
            izz="0.0001"
   />
        </inertial>
    </link>

    <!-- ================ RIGHT WHEEL LINK ================ -->

    <link name="r_wheel">
        <visual>
            <geometry>
                <mesh filename="package://armstrong_description/meshes/r_wheel.dae"/>       
            </geometry>
        </visual>
        <collision>
            <origin rpy="0 0 0" xyz="0 0 0"/>
            <geometry>
                <cylinder radius="${wheel_radius}" length="${wheel_width}"/>
              </geometry>         
        </collision>
        <inertial>
            <origin xyz="0 0 0" rpy="0 0 0" />
            <mass value="0.635" />
            <inertia ixx="0.0001" ixy="0.000"  ixz="0.000"  
            iyy="0.0001" iyz="0.000"
            izz="0.0001"
   />
        </inertial>
    </link>

    <!-- ================ FRONT CASTER ARM LINK ================ -->

    <link name="f_caster_arm">
        <visual>
            <geometry>
                <mesh filename="package://armstrong_description/meshes/caster_arm.dae"/>       
            </geometry>
        </visual>
        <collision>
            <origin rpy="0 0 0" xyz="0 0 0"/>
            <geometry>
                <mesh filename="package://armstrong_description/meshes/caster_arm.dae"/>
            </geometry>            
        </collision>
        <inertial>
            <origin xyz="0 0 0" rpy="0 0 0" />
            <mass value="0.048" />
            <inertia ixx="0.0001" ixy="0.000"  ixz="0.000"  
            iyy="0.0001" iyz="0.000"
            izz="0.0001"
   />
            </inertial>
    </link>

    <!-- ================ FRONT CASTER WHEELS LINK ================ -->

    <link name="f_caster_wheels">
        <visual>
            <geometry>
                <mesh filename="package://armstrong_description/meshes/caster_wheels.dae"/>       
            </geometry>
        </visual>
        <collision>
            <origin rpy="0 0 0" xyz="0 0 0"/>
            <geometry>
                <mesh filename="package://armstrong_description/meshes/caster_wheels.dae"/>
            </geometry>            
        </collision>
        <inertial>
            <origin xyz="0 0 0" rpy="0 0 0" />
            <mass value="0.1516"/>
            <inertia ixx="0.0001" ixy="0.000"  ixz="0.000"  
            iyy="0.0001" iyz="0.000"
            izz="0.0001"
   />
        </inertial>
    </link>

    <!-- ================ BACK CASTER ARM LINK ================ -->

    <link name="b_caster_arm">
        <visual>
            <geometry>
                <mesh filename="package://armstrong_description/meshes/caster_arm.dae"/>       
            </geometry>
        </visual>
        <collision>
            <origin rpy="0 0 0" xyz="0 0 0"/>
            <geometry>
                <mesh filename="package://armstrong_description/meshes/caster_arm.dae"/>
            </geometry>            
        </collision>
        <inertial>
            <origin xyz="0 0 0" rpy="0 0 0" />
            <mass value="0.048" />
            <inertia ixx="0.0001" ixy="0.000"  ixz="0.000"  
            iyy="0.0001" iyz="0.000"
            izz="0.0001"
   />
        </inertial>
    </link>    

    <!-- ================ BACK CASTER WHEELS LINK ================ -->

    <link name="b_caster_wheels">
        <visual>
            <geometry>
                <mesh filename="package://armstrong_description/meshes/caster_wheels.dae"/>       
            </geometry>
        </visual>
        <collision>
            <origin rpy="0 0 0" xyz="0 0 0"/>
            <geometry>
                <mesh filename="package://armstrong_description/meshes/caster_wheels.dae"/>
            </geometry>            
        </collision>
        <inertial>
            <origin xyz="0 0 0" rpy="0 0 0" />
            <mass value="0.1516"/>
            <inertia ixx="0.0001" ixy="0.000"  ixz="0.000"  
            iyy="0.0001" iyz="0.000"
            izz="0.0001"
   />
        </inertial>
    </link>

    <!-- ================ LINK1 LINK ================ -->

    <link name="link_1">
        <visual>
            <geometry>
                <mesh filename="package://armstrong_description/meshes/link_1.dae"/>       
            </geometry>
        </visual>
        <collision>
            <origin rpy="0 0 0" xyz="0 0 0"/>
            <geometry>
                <mesh filename="package://armstrong_description/meshes/link_1.dae"/>       
            </geometry>            
        </collision>
        <inertial>
            <origin xyz="0 0 0" rpy="0 0 0" />
            <mass value="0.266262084814045" />
            <inertia ixx="0.0001" ixy="0.000"  ixz="0.000"  
            iyy="0.0001" iyz="0.000"
            izz="0.0001"
   />   
        </inertial>
    </link>

    <!-- ================ LINK2 LINK ================ -->

    <link name="link_2">
        <visual>
            <geometry>
                <mesh filename="package://armstrong_description/meshes/link_2.dae"/>       
            </geometry>
        </visual>
        <collision>
            <origin rpy="0 0 0" xyz="0 0 0"/>
            <geometry>
                <mesh filename="package://armstrong_description/meshes/link_2.dae"/>
            </geometry>            
        </collision>
        <inertial>
            <origin xyz="0 0 0" rpy="0 0 0" />
            <mass value="0.20557" />
            <inertia ixx="0.0001" ixy="0.000"  ixz="0.000"  
            iyy="0.0001" iyz="0.000"
            izz="0.0001"
   />
            </inertial>
    </link>

    <!-- ================ LINK3 LINK ================ -->

    <link name="link_3">
        <visual>
            <geometry>
                <mesh filename="package://armstrong_description/meshes/link_3.dae"/>       
            </geometry>
        </visual>
        <collision>
            <origin rpy="0 0 0" xyz="0 0 0"/>
            <geometry>
                <mesh filename="package://armstrong_description/meshes/link_3.dae"/>
            </geometry>            
        </collision>
        <inertial>
            <origin xyz="0 0 0" rpy="0 0 0" />
            <mass value="0.145524" />
            <inertia ixx="0.0001" ixy="0.000"  ixz="0.000"  
            iyy="0.0001" iyz="0.000"
            izz="0.0001"
   />    
        </inertial>
    </link>

    <!-- ================ LINK4 LINK ================ -->

    <link name="link_4">
        <visual>
            <geometry>
                <mesh filename="package://armstrong_description/meshes/link_4.dae"/>       
            </geometry>
        </visual>
        <collision>
            <origin rpy="0 0 0" xyz="0 0 0"/>
            <geometry>
                <mesh filename="package://armstrong_description/meshes/link_4.dae"/>
            </geometry>            
        </collision>
        <inertial>
            <origin xyz="0 0 0" rpy="0 0 0" />
            <mass value="1" />
            <inertia ixx="0.0001" ixy="0.000"  ixz="0.000"  
         iyy="0.0001" iyz="0.000"
         izz="0.0001" />
</inertial>
    </link>

    <!-- ================ LINK5 LINK ================ -->

    <link name="link_5">
        <visual>
            <geometry>
                <mesh filename="package://armstrong_description/meshes/link_5.dae"/>       
            </geometry>
        </visual>
        <collision>
            <origin rpy="0 0 0" xyz="0 0 0"/>
            <geometry>
                <mesh filename="package://armstrong_description/meshes/link_5.dae"/>
            </geometry>            
        </collision>
        <inertial>
            <origin xyz="0 0 0" rpy="0 0 0" />
            <mass value="0.092731" />
            <inertia ixx="0.0001" ixy="0.000"  ixz="0.000"  
         iyy="0.0001" iyz="0.000"
         izz="0.0001"
/></inertial>
    </link>

    <!-- ================ LINK6 LINK ================ -->

    <link name="link_6">
        <visual>
            <geometry>
                <mesh filename="package://armstrong_description/meshes/link_6.dae"/>       
            </geometry>
        </visual>
        <collision>
            <origin rpy="0 0 0" xyz="0 0 0"/>
            <geometry>
                <mesh filename="package://armstrong_description/meshes/link_6.dae"/>
            </geometry>            
        </collision>
        <inertial>
            <origin xyz="0 0 0" rpy="0 0 0" />
            <mass value="0.12368" />
            <inertia ixx="0.0001" ixy="0.000"  ixz="0.000"  
            iyy="0.0001" iyz="0.000"
            izz="0.0001"
   /></inertial>
    </link>


    <!-- ================ R_FINGER LINK ================ -->

    <link name="r_finger">
        <visual>
            <geometry>
                <mesh filename="package://armstrong_description/meshes/r_finger.dae"/>       
            </geometry>
        </visual>
        <collision>
            <origin rpy="0 0 0" xyz="0 0 0"/>
            <geometry>
                <mesh filename="package://armstrong_description/meshes/r_finger.dae"/>
            </geometry>            
        </collision>
        <inertial>
            <origin xyz="0 0 0" rpy="0 0 0" />
            <mass value="0.027053" />
            <inertia ixx="0.0001" ixy="0.000"  ixz="0.000"  
            iyy="0.0001" iyz="0.000"
            izz="0.0001"
   />
        </inertial>
    </link>


    <!-- ================ L_FINGER LINK ================ -->

    <link name="l_finger">
        <visual>
            <geometry>
                <mesh filename="package://armstrong_description/meshes/l_finger.dae"/>       
            </geometry>
        </visual>
        <collision>
            <origin rpy="0 0 0" xyz="0 0 0"/>
            <geometry>
                <mesh filename="package://armstrong_description/meshes/l_finger.dae"/>
            </geometry>            
        </collision>
        <inertial>
            <origin xyz="0 0 0" rpy="0 0 0" />
            <mass value="0.027053" />
            <inertia ixx="0.0001" ixy="0.000"  ixz="0.000"  
            iyy="0.0001" iyz="0.000"
            izz="0.0001"
   />
        </inertial>
    </link>

    <!-- ================ END EFFECTOR SPHERE LINK ================ -->

    <link name="end_effector">
        <visual>
            <geometry>
                <sphere radius="0.015"/>
            </geometry>
        </visual>
            <inertial>
        <origin xyz="0 0 0" rpy="0 0 0" />
        <mass value="0" />
        <inertia ixx="0.0001" ixy="0.000"  ixz="0.000"  
        iyy="0.0001" iyz="0.000"
        izz="0.0001"
/>
    </inertial>
    </link>

    <!-- ================ FRAME JOINT ================ -->

    <joint name="joint_base_link" type="fixed">
        <parent link="base_link"/>
        <child  link="frame"/>
        <origin rpy="0 0 0" xyz="0 0 0"/>
    </joint>

    <!-- ================ LEFT WHEEL JOINT ================ -->

    <joint name="joint_l_wheel" type="continuous">
        <parent link="frame"/>
        <child  link="l_wheel"/>
        <origin rpy="0 0 0" xyz="-0.18729 0 0"/>
        <axis xyz="1 0 0"/>
    </joint>

    <transmission name="l_wheel_trans">
        <type>transmission_interface/SimpleTransmission</type>
        <joint name="joint_l_wheel">
            <hardwareInterface>hardware_interface/VelocityJointInterface</hardwareInterface>
        </joint>
        <actuator name="right_wheel_actuator">
            <mechanicalReduction> 1 </mechanicalReduction>
            <hardwareInterface>VelocityJointInterface</hardwareInterface>
        </actuator>
    </transmission>
    
    <!-- ================ RIGHT WHEEL JOINT ================ -->

    <joint name="joint_r_wheel" type="continuous">
        <parent link="frame"/>
        <child  link="r_wheel"/>
        <origin rpy="0 0 0" xyz="0.18729 0 0"/>
        <axis xyz="1 0 0"/>
    </joint>

    <transmission name="r_wheel_trans">
        <type>transmission_interface/SimpleTransmission</type>
        <joint name="joint_r_wheel">
            <hardwareInterface>hardware_interface/VelocityJointInterface</hardwareInterface>
        </joint>
        <actuator name="right_wheel_actuator">
            <mechanicalReduction> 1 </mechanicalReduction>
            <hardwareInterface>VelocityJointInterface</hardwareInterface>
        </actuator>
    </transmission>

    <!-- ================ FRONT CASTER ARM JOINT ================ -->
    
    <joint name="joint_f_caster_arm" type="continuous">
        <parent link="frame"/>
        <child  link="f_caster_arm"/>
        <origin rpy="0 0 0" xyz="0 -0.18518 0.006469"/>
        <axis xyz="0 0 1"/>
    </joint>
    
    <!-- ================ FRONT CASTER WHEELS JOINT ================ -->
    
    <joint name="joint_f_caster_wheels" type="continuous">
        <parent link="f_caster_arm"/>
        <child  link="f_caster_wheels"/>
        <origin rpy="0 0 0" xyz="0 0.0387 -0.0419"/>
        <axis xyz="1 0 0"/>
    </joint>

    <!-- ================ BACK CASTER ARM JOINT ================ -->

    <joint name="joint_b_caster_arm" type="continuous">
        <parent link="frame"/>
        <child  link="b_caster_arm"/>
        <origin rpy="0 0 0" xyz="0 0.18518 0.006469"/>
        <axis xyz="0 0 1"/>
    </joint>

    <!-- ================ BACK CASTER WHEELS JOINT ================ -->

    <joint name="joint_b_caster_wheels" type="continuous">
        <parent link="b_caster_arm"/>
        <child  link="b_caster_wheels"/>
        <origin rpy="0 0 0" xyz="0 0.0387 -0.0419"/>
        <axis xyz="1 0 0"/>
    </joint>

    <!-- ================ LINK1 JOINT ================ -->

    <joint name="joint_1" type="revolute">
        <parent link="frame"/>
        <child  link="link_1"/>
        <origin rpy="0 0 0" xyz="0 0.15508 0.076053"/>
        <axis xyz="0 0 1"/>
        <limit lower="-1.5708" upper="1.5708" effort="24" velocity="6.07"/>
    </joint>

   <xacro:transmission_block joint_name="joint_1"/>

    <!-- ================ LINK2 JOINT ================ -->

    <joint name="joint_2" type="revolute">
        <parent link="link_1"/>
        <child  link="link_2"/>
        <origin rpy="0 0 0" xyz="0 0 0.058757"/>
        <axis xyz="1 0 0"/>
        <limit lower="-1.91288086" upper="1.91288086" effort="48" velocity="6.07"/>
    </joint>

   <xacro:transmission_block joint_name="joint_2"/>

    <!-- ================ LINK3 JOINT ================ -->

    <joint name="joint_3" type="revolute">
        <parent link="link_2"/>
        <child  link="link_3"/>
        <origin rpy="0 0 0" xyz="0 0.031055 0.189"/>
        <axis xyz="1 0 0"/>
        <limit lower="-2.7227136" upper="2.7227136" effort="24" velocity="6.07"/>
    </joint>
    
    <xacro:transmission_block joint_name="joint_3"/>

    <!-- ================ LINK4 JOINT ================ -->

    <joint name="joint_4" type="revolute">
        <parent link="link_3"/>
        <child  link="link_4"/>
        <origin rpy="0 0 0" xyz="0 0 0.0855"/>
        <axis xyz="0 0 1"/>
        <limit lower="-3.14159265" upper="3.14159265" effort="24" velocity="6.07"/>
    </joint>

   <xacro:transmission_block joint_name="joint_4"/>
    
    <!-- ================ LINK5 JOINT ================ -->

    <joint name="joint_5" type="revolute">
        <parent link="link_4"/>
        <child  link="link_5"/>
        <origin rpy="0 0 0" xyz="0 0 0.066188"/>
        <axis xyz="1 0 0"/>
        <limit lower="-1.91288086" upper="1.91288086" effort="24" velocity="6.07"/>
    </joint>

   <xacro:transmission_block joint_name="joint_5"/>

    <!-- ================ LINK6 JOINT ================ -->

    <joint name="joint_6" type="revolute">
        <parent link="link_5"/>
        <child  link="link_6"/>
        <origin rpy="0 0 0" xyz="0 -0.016024 0.08458"/>
        <axis xyz="0 0 1"/>
        <limit lower="-2.617993878" upper="2.617993878" effort="10" velocity="6.07"/>
    </joint>

   <xacro:transmission_block joint_name="joint_6"/>

    <!-- ================ R_FINGER JOINT ================ -->

    <joint name="joint_r_finger" type="revolute">
        <parent link="link_6"/>
        <child  link="r_finger"/>
        <origin rpy="0 0 0" xyz="0.01853 -0.000527 0.05403"/>
        <axis xyz="0 1 0"/>
        <limit lower="-0.40" upper="0" effort="10" velocity="6.07"/>
    </joint>

   <xacro:transmission_block joint_name="joint_r_finger"/>

   <!-- ================ L_FINGER JOINT ================ -->

    <joint name="joint_l_finger" type="revolute">
        <parent link="link_6"/>
        <child  link="l_finger"/>
        <origin rpy="0 0 0" xyz="-0.01853 -0.000527 0.05403"/>
        <axis xyz="0 1 0"/>
        <limit lower="0" upper="0.40" effort="10" velocity="6.07"/>
    </joint>

   <xacro:transmission_block joint_name="joint_l_finger"/>

   <!-- ================ END EFFECTOR JOINT ================ -->

    <joint name="joint_end_effector" type="fixed">
        <parent link="link_6"/>
        <child  link="end_effector"/>
        <origin rpy="0 0 0" xyz="0 -0.077462 0.083028"/>
    </joint>
</robot>